<!-- 
    Copyright 2018 Real-Time Innovations, Inc.
    Copyright 2012 Open Source Robotics Foundation
 
    Licensed under the Apache License, Version 2.0 (the "License");
    you may not use this file except in compliance with the License.
    You may obtain a copy of the License at
    
        http://www.apache.org/licenses/LICENSE-2.0
    
    Unless required by applicable law or agreed to in writing, software
    distributed under the License is distributed on an "AS IS" BASIS,
    WITHOUT WARRANTIES OR CONDITIONS OF ANY KIND, either express or implied.
    See the License for the specific language governing permissions and
    limitations under the License. 
-->
<!-- 
    Copied from: https://bitbucket.org/osrf/gazebo_models/src/c7b4d0ba1ea5d66d03b292f7bef8dc174755aed8/pioneer2dx/model.sdf 
                 http://gazebosim.org/tutorials?tut=sensor_noise
                 https://github.com/ros-simulation/gazebo_ros_pkgs/blob/kinetic-devel/gazebo_plugins/test/test_worlds/elevator.world
-->

<?xml version="1.0" ?>
<sdf version="1.5">
  <world name='default'>
    <light name='sun' type='directional'>
      <cast_shadows>1</cast_shadows>
      <pose>0 0 10 0 -0 0</pose>
      <diffuse>0.8 0.8 0.8 1</diffuse>
      <specular>0.2 0.2 0.2 1</specular>
      <attenuation>
        <range>1000</range>
        <constant>0.9</constant>
        <linear>0.01</linear>
        <quadratic>0.001</quadratic>
      </attenuation>
      <direction>-0.5 0.1 -0.9</direction>
    </light>
    <model name='ground_plane'>
      <static>1</static>
      <link name='link'>
        <collision name='collision'>
          <geometry>
            <plane>
              <normal>0 0 1</normal>
              <size>100 100</size>
            </plane>
          </geometry>
          <surface>
            <friction>
              <ode>
                <mu>100</mu>
                <mu2>50</mu2>
              </ode>
            </friction>
            <bounce/>
            <contact>
              <ode/>
            </contact>
          </surface>
          <max_contacts>10</max_contacts>
        </collision>
        <visual name='visual'>
          <cast_shadows>0</cast_shadows>
          <geometry>
            <plane>
              <normal>0 0 1</normal>
              <size>100 100</size>
            </plane>
          </geometry>
          <material>
            <script>
              <uri>file://media/materials/scripts/gazebo.material</uri>
              <name>Gazebo/Grey</name>
            </script>
          </material>
        </visual>
        <velocity_decay>
          <linear>0</linear>
          <angular>0</angular>
        </velocity_decay>
        <self_collide>0</self_collide>
        <kinematic>0</kinematic>
        <gravity>1</gravity>
      </link>
    </model>

  <!-- 
      Differential drive robot
  -->
  <model name="pioneer2dx">
    <pose>0 -5.4 0.16 0 0 0</pose>
    <link name="chassis">
      <pose>0 0 0.16 0 0 0</pose>
      <inertial>
        <mass>5.67</mass>
        <inertia>
          <ixx>0.07</ixx>
          <iyy>0.08</iyy>
          <izz>0.10</izz>
          <ixy>0</ixy>
          <ixz>0</ixz>
          <iyz>0</iyz>
        </inertia>
      </inertial>
      <collision name="collision">
        <geometry>
          <box>
            <size>0.445 0.277 0.17</size>
          </box>
        </geometry>
      </collision>
      <collision name="castor_collision">
        <pose>-0.200 0 -0.12 0 0 0</pose>
        <geometry>
          <sphere>
            <radius>0.04</radius>
          </sphere>
        </geometry>
        <surface>
          <friction>
            <ode>
              <mu>0</mu>
              <mu2>0</mu2>
              <slip1>1.0</slip1>
              <slip2>1.0</slip2>
            </ode>
          </friction>
        </surface>
      </collision>
      <visual name="visual">
        <pose>0 0 0.04 0 0 0</pose>
        <geometry>
          <mesh>
            <uri>model://pioneer2dx/meshes/chassis.dae</uri>
          </mesh>
        </geometry>
      </visual>
      <visual name="castor_visual">
        <pose>-0.200 0 -0.12 0 0 0</pose>
        <geometry>
          <sphere>
            <radius>0.04</radius>
          </sphere>
        </geometry>
        <material>
          <script>
            <uri>file://media/materials/scripts/gazebo.material</uri>
            <name>Gazebo/FlatBlack</name>
          </script>
        </material>
      </visual>
      
      <!-- 
          Laser sensor
      -->
      <sensor name="laser" type="ray">
        <pose>0.2 0 0 0 -0 0</pose>
        <ray>
          <scan>
            <horizontal>
              <samples>120</samples>
              <resolution>1</resolution>
              <min_angle>-1.2</min_angle>
              <max_angle>1.2</max_angle>
            </horizontal>
          </scan>
          <range>
            <min>0.08</min>
            <max>5</max>
            <resolution>0.01</resolution>
          </range>
          <noise>
            <type>gaussian</type>
            <mean>0.0</mean>
            <stddev>0.01</stddev>
          </noise>
        </ray>
         <plugin name='DdsLaserPlugin' filename='laser_scan/libDdsLaserPlugin.so'>
            <dds_domain_id>0</dds_domain_id>
            <topic_name>laser_scan</topic_name>
            <dds_qos_profile_file></dds_qos_profile_file>
            <dds_qos_profile></dds_qos_profile>
         </plugin>
        <always_on>1</always_on>
        <update_rate>60</update_rate>
        <visualize>true</visualize>
      </sensor>

    </link>
    <link name="right_wheel">
      <pose>0.1 -.17 0.11 0 1.5707 1.5707</pose>
      <inertial>
        <mass>1.5</mass>
        <inertia>
          <ixx>0.0051</ixx>
          <iyy>0.0051</iyy>
          <izz>0.0090</izz>
          <ixy>0</ixy>
          <ixz>0</ixz>
          <iyz>0</iyz>
        </inertia>
      </inertial>
      <collision name="collision">
        <geometry>
          <cylinder>
            <radius>0.11</radius>
            <length>0.05</length>
          </cylinder>
        </geometry>
        <surface>
          <friction>
            <ode>
              <mu>100000.0</mu>
              <mu2>100000.0</mu2>
              <slip1>0.0</slip1>
              <slip2>0.0</slip2>
            </ode>
          </friction>
        </surface>
      </collision>
      <visual name="visual">
        <geometry>
          <cylinder>
            <radius>0.11</radius>
            <length>0.05</length>
          </cylinder>
        </geometry>
        <material>
          <script>
            <uri>file://media/materials/scripts/gazebo.material</uri>
            <name>Gazebo/FlatBlack</name>
          </script>
        </material>
      </visual>
    </link>
    <link name="left_wheel">
      <pose>0.1 .17 0.11 0 1.5707 1.5707</pose>
      <inertial>
        <mass>1.5</mass>
        <inertia>
          <ixx>0.0051</ixx>
          <iyy>0.0051</iyy>
          <izz>0.0090</izz>
          <ixy>0</ixy>
          <ixz>0</ixz>
          <iyz>0</iyz>
        </inertia>
      </inertial>
      <collision name="collision">
        <geometry>
          <cylinder>
            <radius>0.11</radius>
            <length>0.05</length>
          </cylinder>
        </geometry>
        <surface>
          <friction>
            <ode>
              <mu>100000.0</mu>
              <mu2>100000.0</mu2>
              <slip1>0.0</slip1>
              <slip2>0.0</slip2>
            </ode>
          </friction>
        </surface>
      </collision>
      <visual name="visual">
        <geometry>
          <cylinder>
            <radius>0.11</radius>
            <length>0.05</length>
          </cylinder>
        </geometry>
        <material>
          <script>
            <uri>file://media/materials/scripts/gazebo.material</uri>
            <name>Gazebo/FlatBlack</name>
          </script>
        </material>
      </visual>
    </link>
    <joint type="revolute" name="left_wheel_hinge">
      <pose>0 0 -0.03 0 0 0</pose>
      <child>left_wheel</child>
      <parent>chassis</parent>
      <axis>
        <xyz>0 1 0</xyz>
        <use_parent_model_frame>true</use_parent_model_frame>
      </axis>
    </joint>
    <joint type="revolute" name="right_wheel_hinge">
      <pose>0 0 0.03 0 0 0</pose>
      <child>right_wheel</child>
      <parent>chassis</parent>
      <axis>
        <xyz>0 1 0</xyz>
        <use_parent_model_frame>true</use_parent_model_frame>
      </axis>
    </joint>
    <plugin name='differential_drive_controller'
              filename='diff_drive/libDdsDiffDrivePlugin.so'>
      <update_rate>2</update_rate>
      <left_joint>left_wheel_hinge</left_joint>
      <right_joint>right_wheel_hinge</right_joint>
      <dds_domain_id>0</dds_domain_id>
      <dds_qos_profile_file></dds_qos_profile_file>
      <dds_qos_profile></dds_qos_profile>
      <wheel_separation>0.39</wheel_separation>
      <wheel_diameter>0.15</wheel_diameter>
      <wheel_acceleration>0</wheel_acceleration>
      <wheel_torque>5</wheel_torque>
      <topic_name_twist>cmd_vel</topic_name_twist>
      <odometry_source>encoder</odometry_source>
      <topic_name_odometry>odom</topic_name_odometry>
      <topic_name_joint>joint</topic_name_joint>
      <odometryFrame>odom</odometryFrame>
      <legacy_mode>true</legacy_mode>
    </plugin>
  </model>

  <!-- 
      Elevator
  -->
  <plugin filename="libSimEventsPlugin.so" name="elevator_event_plugin">
      <!-- Region on the ground floor, in front of the elevator -->
      <region>
        <name>region1</name>
        <volume>
          <min>1.5 -1 0</min>
          <max>2.5 1 1</max>
        </volume>
      </region>

      <!-- Region on the first floor, in front of the elevator -->
      <region>
        <name>region2</name>
        <volume>
          <min>1.5 -1 3</min>
          <max>2.5 1 4</max>
        </volume>
      </region>

      <!-- Event publisher for ground floor-->
      <event>
        <name>region1_event</name>
        <type>occupied</type>
        <region>region1</region>
        <topic>~/elevator</topic>
        <msg_data>0</msg_data>
      </event>

      <!-- Event publisher for first floor-->
      <event>
        <name>region2_event</name>
        <type>occupied</type>
        <region>region2</region>
        <topic>~/elevator</topic>
        <msg_data>1</msg_data>
      </event>
    </plugin>

    <!-- The elevator car -->
    <model name="elevator">
      <pose>0 0 0.075 0 0 0</pose>
      <link name="link">
        <inertial>
          <mass>800</mass>
        </inertial>

        <collision name="floor_collision">
          <geometry>
            <box>
              <size>2.25 2.25 0.15</size>
            </box>
          </geometry>
        </collision>
        <visual name="floor_visual">
          <geometry>
            <box>
              <size>2.25 2.25 0.15</size>
            </box>
          </geometry>
        </visual>

        <!-- wall1_collision is the wall to the right of the door, when
             facing the door -->
        <collision name="wall1_collision">
          <pose>1.0745 0.5725 1.125 0 0 0</pose>
          <geometry>
            <box>
              <size>0.1 1.15 2.25</size>
            </box>
          </geometry>
        </collision>
        <visual name="wall1_visual">
          <pose>1.0745 0.5725 1.125 0 0 0</pose>
          <geometry>
            <box>
              <size>0.1 1.15 2.25</size>
            </box>
          </geometry>
          <material>
            <script>
              <name>Gazebo/Red</name>
            </script>
          </material>
        </visual>

        <!-- wall2_collision is the wall to the left of the door, when
             facing the door -->
        <collision name="wall2_collision">
          <pose>1.0745 -1.0625 1.125 0 0 0</pose>
          <geometry>
            <box>
              <size>0.1 0.125 2.25</size>
            </box>
          </geometry>
        </collision>
        <visual name="wall2_visual">
          <pose>1.0745 -1.0625 1.125 0 0 0</pose>
          <geometry>
            <box>
              <size>0.1 0.125 2.25</size>
            </box>
          </geometry>
          <material>
            <script>
              <name>Gazebo/Red</name>
            </script>
          </material>
        </visual>
      </link>

      <link name="door">
        <pose>1.0745 -0.5 1.125 0 0 0</pose>
        <collision name="collision">
          <geometry>
            <box>
              <size>0.08 1.0 2.25</size>
            </box>
          </geometry>
        </collision>
        <visual name="visual">
          <geometry>
            <box>
              <size>0.08 1.0 2.25</size>
            </box>
          </geometry>
        </visual>
      </link>

      <joint name="door" type="prismatic">
        <parent>link</parent>
        <child>door</child>
        <axis>
          <xyz>0 1 0</xyz>
          <limit>
            <lower>0</lower>
            <upper>1</upper>
            <effort>10</effort>
          </limit>

          <dynamics>
            <damping>2</damping>
          </dynamics>
        </axis>
      </joint>

      <joint name="lift" type="prismatic">
        <parent>world</parent>
        <child>link</child>
        <axis>
          <xyz>0 0 1</xyz>
          <limit>
            <lower>0</lower>
            <upper>10</upper>
            <effort>100000</effort>
          </limit>

          <dynamics>
            <damping>50</damping>
          </dynamics>
        </axis>
        <physics>
          <ode>
            <implicit_spring_damper>1</implicit_spring_damper>
          </ode>
        </physics>
      </joint>

      <!-- Plugin to control the elevator -->
      <plugin filename="elevator/libDdsElevatorPlugin.so" name="elevator_plugin">
        <lift_joint>elevator::lift</lift_joint>
        <door_joint>elevator::door</door_joint>
        <floor_height>3.075</floor_height>
        <door_wait_time>10</door_wait_time>
        <topic>elevator</topic>
        <topic_name>elevator</topic_name>
        <dds_domain_id>0</dds_domain_id>
        <dds_qos_profile_file></dds_qos_profile_file>
        <dds_qos_profile></dds_qos_profile>
      </plugin>
    </model>

    <!-- Elevator shaft -->
    <model name="elevator_shaft">
      <static>true</static>
      <link name="link">
        <collision name="shaft_wall1_collision">
          <pose>0 1.25 3 0 0 0</pose>
          <geometry>
            <box>
              <size>2.5 0.15 6</size>
            </box>
          </geometry>
        </collision>
        <visual name="shaft_wall1_visual">
          <pose>0 1.25 3 0 0 0</pose>
          <geometry>
            <box>
              <size>2.5 0.15 6</size>
            </box>
          </geometry>
        </visual>

        <collision name="shaft_wall2_collision">
          <pose>0 -1.25 3 0 0 0</pose>
          <geometry>
            <box>
              <size>2.5 0.15 6</size>
            </box>
          </geometry>
        </collision>
        <visual name="shaft_wall2_visual">
          <pose>0 -1.25 3 0 0 0</pose>
          <geometry>
            <box>
              <size>2.5 0.15 6</size>
            </box>
          </geometry>
        </visual>

        <collision name="shaft_wall3_collision">
          <pose>-1.25 0 3 0 0 0</pose>
          <geometry>
            <box>
              <size>0.15 2.7 6</size>
            </box>
          </geometry>
        </collision>
        <visual name="shaft_wall3_visual">
          <pose>-1.25 0 3 0 0 0</pose>
          <geometry>
            <box>
              <size>0.15 2.7 6</size>
            </box>
          </geometry>
        </visual>

        <collision name="floor0_collision">
          <pose>1.19 0 0.075 0 0 0</pose>
          <geometry>
            <box>
              <size>0.12 2.5 0.15</size>
            </box>
          </geometry>
        </collision>
        <visual name="floor0_visual">
          <pose>1.19 0 0.075 0 0 0</pose>
          <geometry>
            <box>
              <size>0.12 2.5 0.15</size>
            </box>
          </geometry>
        </visual>

        <collision name="floor1_collision">
          <pose>1.19 0 3.075 0 0 0</pose>
          <geometry>
            <box>
              <size>0.12 2.5 0.15</size>
            </box>
          </geometry>
        </collision>
        <visual name="floor1_visual">
          <pose>1.19 0 3.075 0 0 0</pose>
          <geometry>
            <box>
              <size>0.12 2.5 0.15</size>
            </box>
          </geometry>
        </visual>
      </link>
    </model>

    <model name="floor0">
      <pose>2.25 0 0.075 0 0 0</pose>
      <static>true</static>
      <link name="link">
        <collision name="floor_collision">
          <geometry>
            <box>
              <size>2.0 5.0 0.15</size>
            </box>
          </geometry>
        </collision>
        <visual name="floor_visual">
          <geometry>
            <box>
              <size>2.0 5.0 0.15</size>
            </box>
          </geometry>
        </visual>
      </link>
    </model>

    <model name="floor1">
      <pose>2.25 0 3.075 0 0 0</pose>
      <static>true</static>
      <link name="link">
        <collision name="floor_collision">
          <geometry>
            <box>
              <size>2.0 5.0 0.15</size>
            </box>
          </geometry>
        </collision>
        <visual name="floor_visual">
          <geometry>
            <box>
              <size>2.0 5.0 0.15</size>
            </box>
          </geometry>
        </visual>
      </link>
    </model>

    <plugin name='DdsApiPlugin' filename='api_plugin/libDdsApiPlugin.so'>
        <dds_domain_id>0</dds_domain_id>
        <!-- <dds_qos_profile_file>/home/alopez/workspaces/dds-gazebo-plugins/resources/xml/ExampleQosProfiles.xml</dds_qos_profile_file>
        <dds_qos_profile>ExampleLibrary::TransientLocalProfile</dds_qos_profile> -->
    </plugin>
  </world>
</sdf>