<!-- 
    Copyright 2018 Real-Time Innovations, Inc.
    Copyright 2012 Open Source Robotics Foundation
 
    Licensed under the Apache License, Version 2.0 (the "License");
    you may not use this file except in compliance with the License.
    You may obtain a copy of the License at
    
        http://www.apache.org/licenses/LICENSE-2.0
    
    Unless required by applicable law or agreed to in writing, software
    distributed under the License is distributed on an "AS IS" BASIS,
    WITHOUT WARRANTIES OR CONDITIONS OF ANY KIND, either express or implied.
    See the License for the specific language governing permissions and
    limitations under the License. 
-->
<!-- 
    Copied from: https://bitbucket.org/osrf/gazebo_models/src/c7b4d0ba1ea5d66d03b292f7bef8dc174755aed8/pioneer3at/model.sdf
-->

<?xml version="1.0" ?>
<sdf version='1.6'> 
  <world name='default'>
    <light name='sun' type='directional'>
      <cast_shadows>1</cast_shadows>
      <pose>0 0 10 0 -0 0</pose>
      <diffuse>0.8 0.8 0.8 1</diffuse>
      <specular>0.2 0.2 0.2 1</specular>
      <attenuation>
        <range>1000</range>
        <constant>0.9</constant>
        <linear>0.01</linear>
        <quadratic>0.001</quadratic>
      </attenuation>
      <direction>0.5 0.1 -0.9</direction>
    </light>
  <model name='ground_plane'>
      <static>1</static>
      <link name='link'>
        <collision name='collision'>
          <geometry>
            <plane>
              <normal>0 0 1</normal>
              <size>100 100</size>
            </plane>
          </geometry>
          <surface>
            <friction>
              <ode>
                <mu>100</mu>
                <mu2>50</mu2>
              </ode>
            </friction>
            <bounce/>
            <contact>
              <ode/>
            </contact>
          </surface>
          <max_contacts>10</max_contacts>
        </collision>
        <visual name='visual'>
          <cast_shadows>0</cast_shadows>
          <geometry>
            <plane>
              <normal>0 0 1</normal>
              <size>100 100</size>
            </plane>
          </geometry>
          <material>
            <script>
              <uri>file://media/materials/scripts/gazebo.material</uri>
              <name>Gazebo/Grey</name>
            </script>
          </material>
        </visual>
        <velocity_decay>
          <linear>0</linear>
          <angular>0</angular>
        </velocity_decay>
        <self_collide>0</self_collide>
        <kinematic>0</kinematic>
        <gravity>1</gravity>
      </link>
    </model>

  <model name="pioneer3at">
      <pose>0 0 0.180 0 0 0</pose>
      <static>false</static>
      <link name="chassis">
        <inertial>
          <mass>14.0</mass>
          <inertia>
            <ixx>0.147116667</ixx>
            <ixy>0.0</ixy>
            <ixz>0.0</ixz>
            <iyy>0.334951167</iyy>
            <iyz>0.0</iyz>
            <izz>0.3978345</izz>
          </inertia>
        </inertial>
        <collision name="collision">
          <geometry>
            <box>
              <size>0.501 0.300 0.19</size>
            </box>
          </geometry>
        </collision>
        <visual name="visual">
          <geometry>
            <mesh>
              <uri>model://pioneer3at/meshes/chassis.dae</uri>
            </mesh>
          </geometry>
        </visual>
      </link>
      <link name="right_front_wheel">
        <pose>0.125 -0.201 -0.06 1.5707 0 0</pose>

        <inertial>
          <mass>1.5</mass>
          <inertia>
            <ixx>0.005240625</ixx>
            <iyy>0.005240625</iyy>
            <izz>0.009075</izz>
            <ixy>0</ixy>
            <ixz>0</ixz>
            <iyz>0</iyz>
          </inertia>
        </inertial>

        <collision name="collision">
          <geometry>
            <cylinder>
              <radius>0.110</radius>
              <length>0.075</length>
            </cylinder>
          </geometry>
          <surface>
            <friction>
              <ode>
                <mu>1</mu>
                <mu2>1</mu2>
                <slip1>0</slip1>
                <slip2>0</slip2>
              </ode>
            </friction>
          </surface>
        </collision>
        <visual name="visual">
          <geometry>
            <mesh>
              <uri>model://pioneer3at/meshes/wheel.dae</uri>
            </mesh>
          </geometry>
        </visual>
      </link>
      <link name="left_front_wheel">
        <pose>0.125 0.201 -0.06 1.5707 0 0</pose>

        <inertial>
          <mass>1.5</mass>
          <inertia>
            <ixx>0.005240625</ixx>
            <iyy>0.005240625</iyy>
            <izz>0.009075</izz>
            <ixy>0</ixy>
            <ixz>0</ixz>
            <iyz>0</iyz>
          </inertia>
        </inertial>

        <collision name="collision">
          <geometry>
            <cylinder>
              <radius>0.110</radius>
              <length>0.075</length>
            </cylinder>
          </geometry>
          <surface>
            <friction>
              <ode>
                <mu>1</mu>
                <mu2>1</mu2>
                <slip1>0</slip1>
                <slip2>0</slip2>
              </ode>
            </friction>
          </surface>
        </collision>
        <visual name="visual">
          <geometry>
            <mesh>
              <uri>model://pioneer3at/meshes/wheel.dae</uri>
            </mesh>
          </geometry>
        </visual>
      </link>
      <link name="right_rear_wheel">
        <pose>-0.125 -0.201 -0.06 1.5707 0 0</pose>

        <inertial>
          <mass>1.5</mass>
          <inertia>
            <ixx>0.005240625</ixx>
            <iyy>0.005240625</iyy>
            <izz>0.009075</izz>
            <ixy>0</ixy>
            <ixz>0</ixz>
            <iyz>0</iyz>
          </inertia>
        </inertial>

        <collision name="collision">
          <geometry>
            <cylinder>
              <radius>0.110</radius>
              <length>0.075</length>
            </cylinder>
          </geometry>
          <surface>
            <friction>
              <ode>
                <mu>1</mu>
                <mu2>1</mu2>
                <slip1>0</slip1>
                <slip2>0</slip2>
              </ode>
            </friction>
          </surface>
        </collision>
        <visual name="visual">
          <geometry>
            <mesh>
              <uri>model://pioneer3at/meshes/wheel.dae</uri>
            </mesh>
          </geometry>
        </visual>
      </link>
      <link name="left_rear_wheel">
        <pose>-0.125 0.201 -0.06 1.5707 0 0</pose>

        <inertial>
          <mass>1.5</mass>
          <inertia>
            <ixx>0.005240625</ixx>
            <iyy>0.005240625</iyy>
            <izz>0.009075</izz>
            <ixy>0</ixy>
            <ixz>0</ixz>
            <iyz>0</iyz>
          </inertia>
        </inertial>

        <collision name="collision">
          <geometry>
            <cylinder>
              <radius>0.110</radius>
              <length>0.075</length>
            </cylinder>
          </geometry>
          <surface>
            <friction>
              <ode>
                <mu>1</mu>
                <mu2>1</mu2>
                <slip1>0</slip1>
                <slip2>0</slip2>
              </ode>
            </friction>
          </surface>
        </collision>
        <visual name="visual">
          <geometry>
            <mesh>
              <uri>model://pioneer3at/meshes/wheel.dae</uri>
            </mesh>
          </geometry>
        </visual>
      </link>
      <joint type="revolute" name="right_front">
        <pose>0 0 0 0 0 0</pose>
        <child>right_front_wheel</child>
        <parent>chassis</parent>
        <axis>
          <xyz>0 1 0</xyz>
          <use_parent_model_frame>true</use_parent_model_frame>
        </axis>
      </joint>
      <joint type="revolute" name="right_rear">
        <pose>0 0 0 0 0 0</pose>
        <child>right_rear_wheel</child>
        <parent>chassis</parent>
        <axis>
          <xyz>0 1 0</xyz>
          <use_parent_model_frame>true</use_parent_model_frame>
        </axis>
      </joint>
      <joint type="revolute" name="left_front">
        <pose>0 0 0 0 0 0</pose>
        <child>left_front_wheel</child>
        <parent>chassis</parent>
        <axis>
          <xyz>0 1 0</xyz>
          <use_parent_model_frame>true</use_parent_model_frame>
        </axis>
      </joint>
      <joint type="revolute" name="left_rear">
        <pose>0 0 0 0 0 0</pose>
        <child>left_rear_wheel</child>
        <parent>chassis</parent>
        <axis>
          <xyz>0 1 0</xyz>
          <use_parent_model_frame>true</use_parent_model_frame>
        </axis>
      </joint>
    <plugin name="SkidSteerDrivePlugin" filename="skid_steer_drive/libDdsSkidSteerDrivePlugin.so">
      <dds_domain_id>0</dds_domain_id>
      <topic_name_twist>cmd_vel</topic_name_twist>
      <topic_name_odometry>odom</topic_name_odometry>
      <topic_name_joint>joint</topic_name_joint>
      <!-- <dds_qos_profile_file>gazebo-dds-plugins/resources/xml/ExampleQosProfiles.xml</dds_qos_profile_file> -->
      <!-- <dds_qos_profile>ExampleLibrary::TransientLocalProfile</dds_qos_profile> -->
      <right_front_joint>right_front</right_front_joint>
      <right_rear_joint>right_rear</right_rear_joint>
      <left_front_joint>left_front</left_front_joint>
      <left_rear_joint>left_rear</left_rear_joint>
      <wheel_separation>0.4</wheel_separation>
      <wheel_diameter>0.15</wheel_diameter>
      <wheel_torque>5.0</wheel_torque>
      <update_rate>2</update_rate>
      <covariance_x>0.0001</covariance_x>
      <covariance_y>0.0001</covariance_y>
      <covariance_yaw>0.01</covariance_yaw>
    </plugin>
  </model>
  </world>
</sdf>
